2019-03-12 23:04:29,187 [MainThread  ] [WARNI]  Отсутствует локальный файл настроек. Файл создан из шаблона local_settings.py.tmpl
2019-03-12 23:04:29,758 [MainThread  ] [ERROR]  No module named 'flask_peewee'
Traceback (most recent call last):
  File "/Users/ivanshadrin/PycharmProjects/hse_proj/ls_source/run.py", line 40, in <module>
    from application import APP
  File "/Users/ivanshadrin/PycharmProjects/hse_proj/ls_source/application.py", line 4, in <module>
    from flask_peewee.db import Database
ModuleNotFoundError: No module named 'flask_peewee'
2019-03-12 23:06:34,854 [MainThread  ] [ERROR]  'user' is an invalid keyword argument for this function
Traceback (most recent call last):
  File "/Users/ivanshadrin/PycharmProjects/hse_proj/ls_source/run.py", line 40, in <module>
    from application import APP
  File "/Users/ivanshadrin/PycharmProjects/hse_proj/ls_source/application.py", line 23, in <module>
    init_models(DB)
  File "/Users/ivanshadrin/PycharmProjects/hse_proj/ls_source/models/__init__.py", line 13, in init_models
    db.database.create_tables(ms)
  File "/Users/ivanshadrin/PycharmProjects/hse_proj/venv/lib/python3.7/site-packages/peewee.py", line 2871, in create_tables
    model.create_table(**options)
  File "/Users/ivanshadrin/PycharmProjects/hse_proj/venv/lib/python3.7/site-packages/peewee.py", line 5846, in create_table
    cls._schema.create_all(safe, **options)
  File "/Users/ivanshadrin/PycharmProjects/hse_proj/venv/lib/python3.7/site-packages/peewee.py", line 5071, in create_all
    self.create_table(safe, **table_options)
  File "/Users/ivanshadrin/PycharmProjects/hse_proj/venv/lib/python3.7/site-packages/peewee.py", line 4957, in create_table
    self.database.execute(self._create_table(safe=safe, **options))
  File "/Users/ivanshadrin/PycharmProjects/hse_proj/venv/lib/python3.7/site-packages/peewee.py", line 2727, in execute
    return self.execute_sql(sql, params, commit=commit)
  File "/Users/ivanshadrin/PycharmProjects/hse_proj/venv/lib/python3.7/site-packages/peewee.py", line 2712, in execute_sql
    cursor = self.cursor(commit)
  File "/Users/ivanshadrin/PycharmProjects/hse_proj/venv/lib/python3.7/site-packages/peewee.py", line 2698, in cursor
    self.connect()
  File "/Users/ivanshadrin/PycharmProjects/hse_proj/venv/lib/python3.7/site-packages/peewee.py", line 2661, in connect
    self._state.set_connection(self._connect())
  File "/Users/ivanshadrin/PycharmProjects/hse_proj/venv/lib/python3.7/site-packages/peewee.py", line 2942, in _connect
    **self.connect_params)
TypeError: 'user' is an invalid keyword argument for this function
2019-03-12 23:09:13,351 [MainThread  ] [ERROR]  'user' is an invalid keyword argument for this function
Traceback (most recent call last):
  File "/Users/ivanshadrin/PycharmProjects/hse_proj/ls_source/run.py", line 40, in <module>
    from application import APP
  File "/Users/ivanshadrin/PycharmProjects/hse_proj/ls_source/application.py", line 23, in <module>
    init_models(DB)
  File "/Users/ivanshadrin/PycharmProjects/hse_proj/ls_source/models/__init__.py", line 13, in init_models
    db.database.create_tables(ms)
  File "/Users/ivanshadrin/PycharmProjects/hse_proj/venv/lib/python3.7/site-packages/peewee.py", line 2871, in create_tables
    model.create_table(**options)
  File "/Users/ivanshadrin/PycharmProjects/hse_proj/venv/lib/python3.7/site-packages/peewee.py", line 5846, in create_table
    cls._schema.create_all(safe, **options)
  File "/Users/ivanshadrin/PycharmProjects/hse_proj/venv/lib/python3.7/site-packages/peewee.py", line 5071, in create_all
    self.create_table(safe, **table_options)
  File "/Users/ivanshadrin/PycharmProjects/hse_proj/venv/lib/python3.7/site-packages/peewee.py", line 4957, in create_table
    self.database.execute(self._create_table(safe=safe, **options))
  File "/Users/ivanshadrin/PycharmProjects/hse_proj/venv/lib/python3.7/site-packages/peewee.py", line 2727, in execute
    return self.execute_sql(sql, params, commit=commit)
  File "/Users/ivanshadrin/PycharmProjects/hse_proj/venv/lib/python3.7/site-packages/peewee.py", line 2712, in execute_sql
    cursor = self.cursor(commit)
  File "/Users/ivanshadrin/PycharmProjects/hse_proj/venv/lib/python3.7/site-packages/peewee.py", line 2698, in cursor
    self.connect()
  File "/Users/ivanshadrin/PycharmProjects/hse_proj/venv/lib/python3.7/site-packages/peewee.py", line 2661, in connect
    self._state.set_connection(self._connect())
  File "/Users/ivanshadrin/PycharmProjects/hse_proj/venv/lib/python3.7/site-packages/peewee.py", line 2942, in _connect
    **self.connect_params)
TypeError: 'user' is an invalid keyword argument for this function
2019-03-12 23:09:54,104 [MainThread  ] [ERROR]  'user' is an invalid keyword argument for this function
Traceback (most recent call last):
  File "/Users/ivanshadrin/PycharmProjects/hse_proj/ls_source/run.py", line 40, in <module>
    from application import APP
  File "/Users/ivanshadrin/PycharmProjects/hse_proj/ls_source/application.py", line 23, in <module>
    init_models(DB)
  File "/Users/ivanshadrin/PycharmProjects/hse_proj/ls_source/models/__init__.py", line 13, in init_models
    db.database.create_tables(ms)
  File "/Users/ivanshadrin/PycharmProjects/hse_proj/venv/lib/python3.7/site-packages/peewee.py", line 2871, in create_tables
    model.create_table(**options)
  File "/Users/ivanshadrin/PycharmProjects/hse_proj/venv/lib/python3.7/site-packages/peewee.py", line 5846, in create_table
    cls._schema.create_all(safe, **options)
  File "/Users/ivanshadrin/PycharmProjects/hse_proj/venv/lib/python3.7/site-packages/peewee.py", line 5071, in create_all
    self.create_table(safe, **table_options)
  File "/Users/ivanshadrin/PycharmProjects/hse_proj/venv/lib/python3.7/site-packages/peewee.py", line 4957, in create_table
    self.database.execute(self._create_table(safe=safe, **options))
  File "/Users/ivanshadrin/PycharmProjects/hse_proj/venv/lib/python3.7/site-packages/peewee.py", line 2727, in execute
    return self.execute_sql(sql, params, commit=commit)
  File "/Users/ivanshadrin/PycharmProjects/hse_proj/venv/lib/python3.7/site-packages/peewee.py", line 2712, in execute_sql
    cursor = self.cursor(commit)
  File "/Users/ivanshadrin/PycharmProjects/hse_proj/venv/lib/python3.7/site-packages/peewee.py", line 2698, in cursor
    self.connect()
  File "/Users/ivanshadrin/PycharmProjects/hse_proj/venv/lib/python3.7/site-packages/peewee.py", line 2661, in connect
    self._state.set_connection(self._connect())
  File "/Users/ivanshadrin/PycharmProjects/hse_proj/venv/lib/python3.7/site-packages/peewee.py", line 2942, in _connect
    **self.connect_params)
TypeError: 'user' is an invalid keyword argument for this function
2019-03-12 23:10:48,937 [MainThread  ] [ERROR]  'DATABASE'
Traceback (most recent call last):
  File "/Users/ivanshadrin/PycharmProjects/hse_proj/ls_source/run.py", line 40, in <module>
    from application import APP
  File "/Users/ivanshadrin/PycharmProjects/hse_proj/ls_source/application.py", line 22, in <module>
    DB = Database(APP)  # Инициируем работу с БД. Тут же создаюётся таблицы, если их нет в БД.
  File "/Users/ivanshadrin/PycharmProjects/hse_proj/venv/lib/python3.7/site-packages/flask_peewee/db.py", line 14, in __init__
    self.load_database()
  File "/Users/ivanshadrin/PycharmProjects/hse_proj/venv/lib/python3.7/site-packages/flask_peewee/db.py", line 21, in load_database
    self.database_config = dict(self.app.config['DATABASE'])
KeyError: 'DATABASE'
2019-03-12 23:11:14,803 [MainThread  ] [ERROR]  Please specify a "name" and "engine" for your database
Traceback (most recent call last):
  File "/Users/ivanshadrin/PycharmProjects/hse_proj/venv/lib/python3.7/site-packages/flask_peewee/db.py", line 23, in load_database
    self.database_name = self.database_config.pop('name')
KeyError: 'name'

During handling of the above exception, another exception occurred:

Traceback (most recent call last):
  File "/Users/ivanshadrin/PycharmProjects/hse_proj/ls_source/run.py", line 40, in <module>
    from application import APP
  File "/Users/ivanshadrin/PycharmProjects/hse_proj/ls_source/application.py", line 22, in <module>
    DB = Database(APP)  # Инициируем работу с БД. Тут же создаюётся таблицы, если их нет в БД.
  File "/Users/ivanshadrin/PycharmProjects/hse_proj/venv/lib/python3.7/site-packages/flask_peewee/db.py", line 14, in __init__
    self.load_database()
  File "/Users/ivanshadrin/PycharmProjects/hse_proj/venv/lib/python3.7/site-packages/flask_peewee/db.py", line 26, in load_database
    raise ImproperlyConfigured('Please specify a "name" and "engine" for your database')
flask_peewee.exceptions.ImproperlyConfigured: Please specify a "name" and "engine" for your database
2019-03-12 23:12:05,757 [MainThread  ] [WARNI]   * Debugger is active!
2019-03-12 23:15:42,236 [MainThread  ] [ERROR]  cannot import name 'ProductAdditional' from 'models.product' (/Users/ivanshadrin/PycharmProjects/hse_proj/ls_source/models/product.py)
Traceback (most recent call last):
  File "/Users/ivanshadrin/PycharmProjects/hse_proj/ls_source/run.py", line 40, in <module>
    from application import APP
  File "/Users/ivanshadrin/PycharmProjects/hse_proj/ls_source/application.py", line 23, in <module>
    init_models(DB)
  File "/Users/ivanshadrin/PycharmProjects/hse_proj/ls_source/models/__init__.py", line 9, in init_models
    from models.product import Product, ProductAdditional
ImportError: cannot import name 'ProductAdditional' from 'models.product' (/Users/ivanshadrin/PycharmProjects/hse_proj/ls_source/models/product.py)
2019-03-12 23:21:22,442 [MainThread  ] [ERROR]  __init__() got an unexpected keyword argument 'options'
Traceback (most recent call last):
  File "/Users/ivanshadrin/PycharmProjects/hse_proj/ls_source/run.py", line 40, in <module>
    from application import APP
  File "/Users/ivanshadrin/PycharmProjects/hse_proj/ls_source/application.py", line 23, in <module>
    init_models(DB)
  File "/Users/ivanshadrin/PycharmProjects/hse_proj/ls_source/models/__init__.py", line 8, in init_models
    from models.order import Order, OrderItem
  File "/Users/ivanshadrin/PycharmProjects/hse_proj/ls_source/models/order.py", line 8, in <module>
    from models.product import Product, ProductAdditional
  File "/Users/ivanshadrin/PycharmProjects/hse_proj/ls_source/models/product.py", line 10, in <module>
    class Product(DB.Model):
  File "/Users/ivanshadrin/PycharmProjects/hse_proj/ls_source/models/product.py", line 17, in Product
    size = CharField(options = ['small', 'medium', 'large'])
  File "/Users/ivanshadrin/PycharmProjects/hse_proj/venv/lib/python3.7/site-packages/peewee.py", line 4129, in __init__
    super(CharField, self).__init__(*args, **kwargs)
TypeError: __init__() got an unexpected keyword argument 'options'
2019-03-12 23:23:07,471 [MainThread  ] [ERROR]  No module named 'models.producers'
Traceback (most recent call last):
  File "/Users/ivanshadrin/PycharmProjects/hse_proj/ls_source/run.py", line 40, in <module>
    from application import APP
  File "/Users/ivanshadrin/PycharmProjects/hse_proj/ls_source/application.py", line 23, in <module>
    init_models(DB)
  File "/Users/ivanshadrin/PycharmProjects/hse_proj/ls_source/models/__init__.py", line 8, in init_models
    from models.order import Order, OrderItem
  File "/Users/ivanshadrin/PycharmProjects/hse_proj/ls_source/models/order.py", line 9, in <module>
    from models.producers import Producer
ModuleNotFoundError: No module named 'models.producers'
2019-03-12 23:23:28,750 [MainThread  ] [WARNI]   * Debugger is active!
2019-03-12 23:28:10,392 [MainThread  ] [ERROR]  name 'Category' is not defined
Traceback (most recent call last):
  File "/Users/ivanshadrin/PycharmProjects/hse_proj/ls_source/run.py", line 40, in <module>
    from application import APP
  File "/Users/ivanshadrin/PycharmProjects/hse_proj/ls_source/application.py", line 28, in <module>
    ADMIN = init_admin(APP, DB)  # Инициируем Админку
  File "/Users/ivanshadrin/PycharmProjects/hse_proj/ls_source/ui/admin.py", line 30, in init_admin
    admin.register(Category)
NameError: name 'Category' is not defined
2019-03-12 23:28:22,548 [MainThread  ] [WARNI]   * Debugger is active!
2019-03-12 23:32:18,553 [MainThread  ] [WARNI]   * Debugger is active!
2019-03-12 23:35:17,849 [MainThread  ] [ERROR]  No module named 'models.category'
Traceback (most recent call last):
  File "/Users/ivanshadrin/PycharmProjects/hse_proj/ls_source/run.py", line 40, in <module>
    from application import APP
  File "/Users/ivanshadrin/PycharmProjects/hse_proj/ls_source/application.py", line 23, in <module>
    init_models(DB)
  File "/Users/ivanshadrin/PycharmProjects/hse_proj/ls_source/models/__init__.py", line 8, in init_models
    from models.order import Order, OrderItem
  File "/Users/ivanshadrin/PycharmProjects/hse_proj/ls_source/models/order.py", line 8, in <module>
    from models.product import Product, ProductAdditional
  File "/Users/ivanshadrin/PycharmProjects/hse_proj/ls_source/models/product.py", line 7, in <module>
    from models.category import Category
ModuleNotFoundError: No module named 'models.category'
2019-03-12 23:36:24,736 [MainThread  ] [ERROR]  name 'Category' is not defined
Traceback (most recent call last):
  File "/Users/ivanshadrin/PycharmProjects/hse_proj/ls_source/run.py", line 40, in <module>
    from application import APP
  File "/Users/ivanshadrin/PycharmProjects/hse_proj/ls_source/application.py", line 23, in <module>
    init_models(DB)
  File "/Users/ivanshadrin/PycharmProjects/hse_proj/ls_source/models/__init__.py", line 8, in init_models
    from models.order import Order, OrderItem
  File "/Users/ivanshadrin/PycharmProjects/hse_proj/ls_source/models/order.py", line 8, in <module>
    from models.product import Product, ProductAdditional
  File "/Users/ivanshadrin/PycharmProjects/hse_proj/ls_source/models/product.py", line 10, in <module>
    class Product(DB.Model):
  File "/Users/ivanshadrin/PycharmProjects/hse_proj/ls_source/models/product.py", line 19, in Product
    category_id = ForeignKeyField(Category, to_field='category_id', null=False)
NameError: name 'Category' is not defined
2019-03-12 23:40:28,645 [MainThread  ] [WARNI]   * Debugger is active!
2019-03-13 01:25:46,707 [MainThread  ] [ERROR]  No module named 'flask.current_app'
Traceback (most recent call last):
  File "/Users/ivanshadrin/PycharmProjects/hse_proj/ls_source/run.py", line 40, in <module>
    from application import APP
  File "/Users/ivanshadrin/PycharmProjects/hse_proj/ls_source/application.py", line 23, in <module>
    init_models(DB)
  File "/Users/ivanshadrin/PycharmProjects/hse_proj/ls_source/models/__init__.py", line 6, in init_models
    from models.category import Category
  File "/Users/ivanshadrin/PycharmProjects/hse_proj/ls_source/models/category.py", line 5, in <module>
    from flask.current_app import DB
ModuleNotFoundError: No module named 'flask.current_app'
2019-03-13 23:38:17,502 [MainThread  ] [WARNI]   * Debugger is active!
2019-03-15 22:01:11,960 [MainThread  ] [WARNI]   * Debugger is active!
2019-03-15 23:30:26,408 [MainThread  ] [WARNI]   * Debugger is active!
2019-03-16 11:08:45,683 [MainThread  ] [ERROR]  No module named 'flask_peewee'
Traceback (most recent call last):
  File "run.py", line 40, in <module>
    from application import APP
  File "/Users/ivanshadrin/PycharmProjects/hse_proj/ls_source/application.py", line 4, in <module>
    from flask_peewee.db import Database
ModuleNotFoundError: No module named 'flask_peewee'
2019-03-16 11:10:01,327 [MainThread  ] [ERROR]  [Errno 48] Address already in use
Traceback (most recent call last):
  File "run.py", line 41, in <module>
    APP.run()
  File "/Users/ivanshadrin/PycharmProjects/hse_proj/venv/lib/python3.7/site-packages/flask/app.py", line 943, in run
    run_simple(host, port, self, **options)
  File "/Users/ivanshadrin/PycharmProjects/hse_proj/venv/lib/python3.7/site-packages/werkzeug/serving.py", line 795, in run_simple
    s.bind(get_sockaddr(hostname, port, address_family))
OSError: [Errno 48] Address already in use
2019-03-16 11:13:42,831 [MainThread  ] [WARNI]   * Debugger is active!
2019-03-16 11:17:25,910 [MainThread  ] [ERROR]  [Errno 48] Address already in use
Traceback (most recent call last):
  File "/Users/ivanshadrin/PycharmProjects/hse_proj/ls_source/run.py", line 41, in <module>
    APP.run()
  File "/Users/ivanshadrin/PycharmProjects/hse_proj/venv/lib/python3.7/site-packages/flask/app.py", line 943, in run
    run_simple(host, port, self, **options)
  File "/Users/ivanshadrin/PycharmProjects/hse_proj/venv/lib/python3.7/site-packages/werkzeug/serving.py", line 795, in run_simple
    s.bind(get_sockaddr(hostname, port, address_family))
OSError: [Errno 48] Address already in use
2019-03-16 11:17:29,391 [MainThread  ] [ERROR]  [Errno 48] Address already in use
Traceback (most recent call last):
  File "/Users/ivanshadrin/PycharmProjects/hse_proj/ls_source/run.py", line 41, in <module>
    APP.run()
  File "/Users/ivanshadrin/PycharmProjects/hse_proj/venv/lib/python3.7/site-packages/flask/app.py", line 943, in run
    run_simple(host, port, self, **options)
  File "/Users/ivanshadrin/PycharmProjects/hse_proj/venv/lib/python3.7/site-packages/werkzeug/serving.py", line 795, in run_simple
    s.bind(get_sockaddr(hostname, port, address_family))
OSError: [Errno 48] Address already in use
2019-03-16 11:17:31,202 [MainThread  ] [ERROR]  [Errno 48] Address already in use
Traceback (most recent call last):
  File "/Users/ivanshadrin/PycharmProjects/hse_proj/ls_source/run.py", line 41, in <module>
    APP.run()
  File "/Users/ivanshadrin/PycharmProjects/hse_proj/venv/lib/python3.7/site-packages/flask/app.py", line 943, in run
    run_simple(host, port, self, **options)
  File "/Users/ivanshadrin/PycharmProjects/hse_proj/venv/lib/python3.7/site-packages/werkzeug/serving.py", line 795, in run_simple
    s.bind(get_sockaddr(hostname, port, address_family))
OSError: [Errno 48] Address already in use
2019-03-16 11:17:37,949 [MainThread  ] [ERROR]  [Errno 48] Address already in use
Traceback (most recent call last):
  File "/Users/ivanshadrin/PycharmProjects/hse_proj/ls_source/run.py", line 41, in <module>
    APP.run()
  File "/Users/ivanshadrin/PycharmProjects/hse_proj/venv/lib/python3.7/site-packages/flask/app.py", line 943, in run
    run_simple(host, port, self, **options)
  File "/Users/ivanshadrin/PycharmProjects/hse_proj/venv/lib/python3.7/site-packages/werkzeug/serving.py", line 795, in run_simple
    s.bind(get_sockaddr(hostname, port, address_family))
OSError: [Errno 48] Address already in use
2019-03-16 11:18:21,218 [MainThread  ] [WARNI]   * Debugger is active!
2019-03-16 12:11:37,235 [MainThread  ] [WARNI]   * Debugger is active!
2019-03-16 12:12:36,363 [MainThread  ] [WARNI]   * Debugger is active!
2019-03-16 12:13:31,795 [MainThread  ] [WARNI]   * Debugger is active!
2019-03-16 12:14:53,729 [MainThread  ] [WARNI]   * Debugger is active!
2019-03-16 12:24:38,864 [MainThread  ] [WARNI]   * Debugger is active!
2019-03-16 12:50:34,358 [MainThread  ] [WARNI]   * Debugger is active!
2019-03-16 12:50:56,083 [MainThread  ] [WARNI]   * Debugger is active!
2019-03-16 12:56:23,718 [MainThread  ] [ERROR]  invalid syntax (order.py, line 26)
Traceback (most recent call last):
  File "/Users/ivanshadrin/PycharmProjects/hse_proj/ls_source/run.py", line 40, in <module>
    from application import APP
  File "/Users/ivanshadrin/PycharmProjects/hse_proj/ls_source/application.py", line 23, in <module>
    init_models(DB)
  File "/Users/ivanshadrin/PycharmProjects/hse_proj/ls_source/models/__init__.py", line 8, in init_models
    from models.order import Order, OrderItem
  File "/Users/ivanshadrin/PycharmProjects/hse_proj/ls_source/models/order.py", line 26
    producer_id = ForeignKeyField(Producer, to_field='producer_id', null=False, default=)
                                                                                        ^
SyntaxError: invalid syntax
2019-03-16 13:10:26,424 [MainThread  ] [ERROR]  name 'matcher' is not defined
Traceback (most recent call last):
  File "/Users/ivanshadrin/PycharmProjects/hse_proj/ls_source/run.py", line 40, in <module>
    from application import APP
  File "/Users/ivanshadrin/PycharmProjects/hse_proj/ls_source/application.py", line 23, in <module>
    init_models(DB)
  File "/Users/ivanshadrin/PycharmProjects/hse_proj/ls_source/models/__init__.py", line 8, in init_models
    from models.order import Order, OrderItem
  File "/Users/ivanshadrin/PycharmProjects/hse_proj/ls_source/models/order.py", line 20, in <module>
    class Order(DB.Model):
  File "/Users/ivanshadrin/PycharmProjects/hse_proj/ls_source/models/order.py", line 26, in Order
    producer_id = ForeignKeyField(Producer, to_field='producer_id', null=False, default=matcher(customer_id))
NameError: name 'matcher' is not defined
2019-03-16 13:12:19,359 [MainThread  ] [ERROR]  no such column: t1.district
Traceback (most recent call last):
  File "/Users/ivanshadrin/PycharmProjects/hse_proj/venv/lib/python3.7/site-packages/peewee.py", line 2714, in execute_sql
    cursor.execute(sql, params or ())
sqlite3.OperationalError: no such column: t1.district

During handling of the above exception, another exception occurred:

Traceback (most recent call last):
  File "/Users/ivanshadrin/PycharmProjects/hse_proj/ls_source/run.py", line 40, in <module>
    from application import APP
  File "/Users/ivanshadrin/PycharmProjects/hse_proj/ls_source/application.py", line 23, in <module>
    init_models(DB)
  File "/Users/ivanshadrin/PycharmProjects/hse_proj/ls_source/models/__init__.py", line 8, in init_models
    from models.order import Order, OrderItem
  File "/Users/ivanshadrin/PycharmProjects/hse_proj/ls_source/models/order.py", line 21, in <module>
    class Order(DB.Model):
  File "/Users/ivanshadrin/PycharmProjects/hse_proj/ls_source/models/order.py", line 27, in Order
    producer_id = ForeignKeyField(Producer, to_field='producer_id', null=False, default=matcher(customer_id))
  File "/Users/ivanshadrin/PycharmProjects/hse_proj/ls_source/logics/some.py", line 8, in matcher
    for producer in Producer.select().where(Producer.district == cust.district):  # TODO: добавить проверку на раб часы
  File "/Users/ivanshadrin/PycharmProjects/hse_proj/venv/lib/python3.7/site-packages/peewee.py", line 6032, in __iter__
    self.execute()
  File "/Users/ivanshadrin/PycharmProjects/hse_proj/venv/lib/python3.7/site-packages/peewee.py", line 1625, in inner
    return method(self, database, *args, **kwargs)
  File "/Users/ivanshadrin/PycharmProjects/hse_proj/venv/lib/python3.7/site-packages/peewee.py", line 1696, in execute
    return self._execute(database)
  File "/Users/ivanshadrin/PycharmProjects/hse_proj/venv/lib/python3.7/site-packages/peewee.py", line 1847, in _execute
    cursor = database.execute(self)
  File "/Users/ivanshadrin/PycharmProjects/hse_proj/venv/lib/python3.7/site-packages/peewee.py", line 2727, in execute
    return self.execute_sql(sql, params, commit=commit)
  File "/Users/ivanshadrin/PycharmProjects/hse_proj/venv/lib/python3.7/site-packages/peewee.py", line 2721, in execute_sql
    self.commit()
  File "/Users/ivanshadrin/PycharmProjects/hse_proj/venv/lib/python3.7/site-packages/peewee.py", line 2512, in __exit__
    reraise(new_type, new_type(*exc_args), traceback)
  File "/Users/ivanshadrin/PycharmProjects/hse_proj/venv/lib/python3.7/site-packages/peewee.py", line 186, in reraise
    raise value.with_traceback(tb)
  File "/Users/ivanshadrin/PycharmProjects/hse_proj/venv/lib/python3.7/site-packages/peewee.py", line 2714, in execute_sql
    cursor.execute(sql, params or ())
peewee.OperationalError: no such column: t1.district
2019-03-16 13:13:20,776 [MainThread  ] [ERROR]  no such table: producers
Traceback (most recent call last):
  File "/Users/ivanshadrin/PycharmProjects/hse_proj/venv/lib/python3.7/site-packages/peewee.py", line 2714, in execute_sql
    cursor.execute(sql, params or ())
sqlite3.OperationalError: no such table: producers

During handling of the above exception, another exception occurred:

Traceback (most recent call last):
  File "/Users/ivanshadrin/PycharmProjects/hse_proj/ls_source/run.py", line 40, in <module>
    from application import APP
  File "/Users/ivanshadrin/PycharmProjects/hse_proj/ls_source/application.py", line 23, in <module>
    init_models(DB)
  File "/Users/ivanshadrin/PycharmProjects/hse_proj/ls_source/models/__init__.py", line 8, in init_models
    from models.order import Order, OrderItem
  File "/Users/ivanshadrin/PycharmProjects/hse_proj/ls_source/models/order.py", line 21, in <module>
    class Order(DB.Model):
  File "/Users/ivanshadrin/PycharmProjects/hse_proj/ls_source/models/order.py", line 27, in Order
    producer_id = ForeignKeyField(Producer, to_field='producer_id', null=False, default=matcher(customer_id))
  File "/Users/ivanshadrin/PycharmProjects/hse_proj/ls_source/logics/some.py", line 8, in matcher
    for producer in Producer.select().where(Producer.district == cust.district):  # TODO: добавить проверку на раб часы
  File "/Users/ivanshadrin/PycharmProjects/hse_proj/venv/lib/python3.7/site-packages/peewee.py", line 6032, in __iter__
    self.execute()
  File "/Users/ivanshadrin/PycharmProjects/hse_proj/venv/lib/python3.7/site-packages/peewee.py", line 1625, in inner
    return method(self, database, *args, **kwargs)
  File "/Users/ivanshadrin/PycharmProjects/hse_proj/venv/lib/python3.7/site-packages/peewee.py", line 1696, in execute
    return self._execute(database)
  File "/Users/ivanshadrin/PycharmProjects/hse_proj/venv/lib/python3.7/site-packages/peewee.py", line 1847, in _execute
    cursor = database.execute(self)
  File "/Users/ivanshadrin/PycharmProjects/hse_proj/venv/lib/python3.7/site-packages/peewee.py", line 2727, in execute
    return self.execute_sql(sql, params, commit=commit)
  File "/Users/ivanshadrin/PycharmProjects/hse_proj/venv/lib/python3.7/site-packages/peewee.py", line 2721, in execute_sql
    self.commit()
  File "/Users/ivanshadrin/PycharmProjects/hse_proj/venv/lib/python3.7/site-packages/peewee.py", line 2512, in __exit__
    reraise(new_type, new_type(*exc_args), traceback)
  File "/Users/ivanshadrin/PycharmProjects/hse_proj/venv/lib/python3.7/site-packages/peewee.py", line 186, in reraise
    raise value.with_traceback(tb)
  File "/Users/ivanshadrin/PycharmProjects/hse_proj/venv/lib/python3.7/site-packages/peewee.py", line 2714, in execute_sql
    cursor.execute(sql, params or ())
peewee.OperationalError: no such table: producers
2019-03-16 13:16:11,023 [MainThread  ] [WARNI]   * Debugger is active!
2019-03-16 13:33:46,736 [MainThread  ] [WARNI]   * Debugger is active!
2019-03-16 15:29:41,757 [MainThread  ] [WARNI]   * Debugger is active!
2019-03-16 15:40:59,488 [MainThread  ] [WARNI]   * Debugger is active!
2019-03-16 15:45:12,477 [MainThread  ] [WARNI]   * Debugger is active!
2019-03-16 15:50:47,360 [MainThread  ] [WARNI]   * Debugger is active!
2019-03-16 15:51:29,884 [MainThread  ] [WARNI]   * Debugger is active!
2019-03-16 15:55:25,792 [MainThread  ] [WARNI]   * Debugger is active!
2019-03-16 19:28:42,744 [MainThread  ] [ERROR]  unable to open database file
Traceback (most recent call last):
  File "/Users/ivanshadrin/PycharmProjects/hse_proj/venv/lib/python3.7/site-packages/peewee.py", line 2661, in connect
    self._state.set_connection(self._connect())
  File "/Users/ivanshadrin/PycharmProjects/hse_proj/venv/lib/python3.7/site-packages/peewee.py", line 2942, in _connect
    **self.connect_params)
sqlite3.OperationalError: unable to open database file

During handling of the above exception, another exception occurred:

Traceback (most recent call last):
  File "/Users/ivanshadrin/PycharmProjects/hse_proj/venv/lib/python3.7/site-packages/peewee.py", line 2712, in execute_sql
    cursor = self.cursor(commit)
  File "/Users/ivanshadrin/PycharmProjects/hse_proj/venv/lib/python3.7/site-packages/peewee.py", line 2698, in cursor
    self.connect()
  File "/Users/ivanshadrin/PycharmProjects/hse_proj/venv/lib/python3.7/site-packages/peewee.py", line 2662, in connect
    self._initialize_connection(self._state.conn)
  File "/Users/ivanshadrin/PycharmProjects/hse_proj/venv/lib/python3.7/site-packages/peewee.py", line 2512, in __exit__
    reraise(new_type, new_type(*exc_args), traceback)
  File "/Users/ivanshadrin/PycharmProjects/hse_proj/venv/lib/python3.7/site-packages/peewee.py", line 186, in reraise
    raise value.with_traceback(tb)
  File "/Users/ivanshadrin/PycharmProjects/hse_proj/venv/lib/python3.7/site-packages/peewee.py", line 2661, in connect
    self._state.set_connection(self._connect())
  File "/Users/ivanshadrin/PycharmProjects/hse_proj/venv/lib/python3.7/site-packages/peewee.py", line 2942, in _connect
    **self.connect_params)
peewee.OperationalError: unable to open database file

During handling of the above exception, another exception occurred:

Traceback (most recent call last):
  File "/Users/ivanshadrin/PycharmProjects/hse_proj3/ls_source/run.py", line 40, in <module>
    from application import APP
  File "/Users/ivanshadrin/PycharmProjects/hse_proj3/ls_source/application.py", line 23, in <module>
    init_models(DB)
  File "/Users/ivanshadrin/PycharmProjects/hse_proj3/ls_source/models/__init__.py", line 14, in init_models
    db.database.create_tables(ms)
  File "/Users/ivanshadrin/PycharmProjects/hse_proj/venv/lib/python3.7/site-packages/peewee.py", line 2871, in create_tables
    model.create_table(**options)
  File "/Users/ivanshadrin/PycharmProjects/hse_proj/venv/lib/python3.7/site-packages/peewee.py", line 5846, in create_table
    cls._schema.create_all(safe, **options)
  File "/Users/ivanshadrin/PycharmProjects/hse_proj/venv/lib/python3.7/site-packages/peewee.py", line 5071, in create_all
    self.create_table(safe, **table_options)
  File "/Users/ivanshadrin/PycharmProjects/hse_proj/venv/lib/python3.7/site-packages/peewee.py", line 4957, in create_table
    self.database.execute(self._create_table(safe=safe, **options))
  File "/Users/ivanshadrin/PycharmProjects/hse_proj/venv/lib/python3.7/site-packages/peewee.py", line 2727, in execute
    return self.execute_sql(sql, params, commit=commit)
  File "/Users/ivanshadrin/PycharmProjects/hse_proj/venv/lib/python3.7/site-packages/peewee.py", line 2721, in execute_sql
    self.commit()
  File "/Users/ivanshadrin/PycharmProjects/hse_proj/venv/lib/python3.7/site-packages/peewee.py", line 2512, in __exit__
    reraise(new_type, new_type(*exc_args), traceback)
  File "/Users/ivanshadrin/PycharmProjects/hse_proj/venv/lib/python3.7/site-packages/peewee.py", line 186, in reraise
    raise value.with_traceback(tb)
  File "/Users/ivanshadrin/PycharmProjects/hse_proj/venv/lib/python3.7/site-packages/peewee.py", line 2712, in execute_sql
    cursor = self.cursor(commit)
  File "/Users/ivanshadrin/PycharmProjects/hse_proj/venv/lib/python3.7/site-packages/peewee.py", line 2698, in cursor
    self.connect()
  File "/Users/ivanshadrin/PycharmProjects/hse_proj/venv/lib/python3.7/site-packages/peewee.py", line 2662, in connect
    self._initialize_connection(self._state.conn)
  File "/Users/ivanshadrin/PycharmProjects/hse_proj/venv/lib/python3.7/site-packages/peewee.py", line 2512, in __exit__
    reraise(new_type, new_type(*exc_args), traceback)
  File "/Users/ivanshadrin/PycharmProjects/hse_proj/venv/lib/python3.7/site-packages/peewee.py", line 186, in reraise
    raise value.with_traceback(tb)
  File "/Users/ivanshadrin/PycharmProjects/hse_proj/venv/lib/python3.7/site-packages/peewee.py", line 2661, in connect
    self._state.set_connection(self._connect())
  File "/Users/ivanshadrin/PycharmProjects/hse_proj/venv/lib/python3.7/site-packages/peewee.py", line 2942, in _connect
    **self.connect_params)
peewee.OperationalError: unable to open database file
2019-03-16 19:29:17,341 [MainThread  ] [ERROR]  unable to open database file
Traceback (most recent call last):
  File "/Users/ivanshadrin/PycharmProjects/hse_proj/venv/lib/python3.7/site-packages/peewee.py", line 2661, in connect
    self._state.set_connection(self._connect())
  File "/Users/ivanshadrin/PycharmProjects/hse_proj/venv/lib/python3.7/site-packages/peewee.py", line 2942, in _connect
    **self.connect_params)
sqlite3.OperationalError: unable to open database file

During handling of the above exception, another exception occurred:

Traceback (most recent call last):
  File "/Users/ivanshadrin/PycharmProjects/hse_proj/venv/lib/python3.7/site-packages/peewee.py", line 2712, in execute_sql
    cursor = self.cursor(commit)
  File "/Users/ivanshadrin/PycharmProjects/hse_proj/venv/lib/python3.7/site-packages/peewee.py", line 2698, in cursor
    self.connect()
  File "/Users/ivanshadrin/PycharmProjects/hse_proj/venv/lib/python3.7/site-packages/peewee.py", line 2662, in connect
    self._initialize_connection(self._state.conn)
  File "/Users/ivanshadrin/PycharmProjects/hse_proj/venv/lib/python3.7/site-packages/peewee.py", line 2512, in __exit__
    reraise(new_type, new_type(*exc_args), traceback)
  File "/Users/ivanshadrin/PycharmProjects/hse_proj/venv/lib/python3.7/site-packages/peewee.py", line 186, in reraise
    raise value.with_traceback(tb)
  File "/Users/ivanshadrin/PycharmProjects/hse_proj/venv/lib/python3.7/site-packages/peewee.py", line 2661, in connect
    self._state.set_connection(self._connect())
  File "/Users/ivanshadrin/PycharmProjects/hse_proj/venv/lib/python3.7/site-packages/peewee.py", line 2942, in _connect
    **self.connect_params)
peewee.OperationalError: unable to open database file

During handling of the above exception, another exception occurred:

Traceback (most recent call last):
  File "/Users/ivanshadrin/PycharmProjects/hse_proj3/ls_source/run.py", line 40, in <module>
    from application import APP
  File "/Users/ivanshadrin/PycharmProjects/hse_proj3/ls_source/application.py", line 23, in <module>
    init_models(DB)
  File "/Users/ivanshadrin/PycharmProjects/hse_proj3/ls_source/models/__init__.py", line 14, in init_models
    db.database.create_tables(ms)
  File "/Users/ivanshadrin/PycharmProjects/hse_proj/venv/lib/python3.7/site-packages/peewee.py", line 2871, in create_tables
    model.create_table(**options)
  File "/Users/ivanshadrin/PycharmProjects/hse_proj/venv/lib/python3.7/site-packages/peewee.py", line 5846, in create_table
    cls._schema.create_all(safe, **options)
  File "/Users/ivanshadrin/PycharmProjects/hse_proj/venv/lib/python3.7/site-packages/peewee.py", line 5071, in create_all
    self.create_table(safe, **table_options)
  File "/Users/ivanshadrin/PycharmProjects/hse_proj/venv/lib/python3.7/site-packages/peewee.py", line 4957, in create_table
    self.database.execute(self._create_table(safe=safe, **options))
  File "/Users/ivanshadrin/PycharmProjects/hse_proj/venv/lib/python3.7/site-packages/peewee.py", line 2727, in execute
    return self.execute_sql(sql, params, commit=commit)
  File "/Users/ivanshadrin/PycharmProjects/hse_proj/venv/lib/python3.7/site-packages/peewee.py", line 2721, in execute_sql
    self.commit()
  File "/Users/ivanshadrin/PycharmProjects/hse_proj/venv/lib/python3.7/site-packages/peewee.py", line 2512, in __exit__
    reraise(new_type, new_type(*exc_args), traceback)
  File "/Users/ivanshadrin/PycharmProjects/hse_proj/venv/lib/python3.7/site-packages/peewee.py", line 186, in reraise
    raise value.with_traceback(tb)
  File "/Users/ivanshadrin/PycharmProjects/hse_proj/venv/lib/python3.7/site-packages/peewee.py", line 2712, in execute_sql
    cursor = self.cursor(commit)
  File "/Users/ivanshadrin/PycharmProjects/hse_proj/venv/lib/python3.7/site-packages/peewee.py", line 2698, in cursor
    self.connect()
  File "/Users/ivanshadrin/PycharmProjects/hse_proj/venv/lib/python3.7/site-packages/peewee.py", line 2662, in connect
    self._initialize_connection(self._state.conn)
  File "/Users/ivanshadrin/PycharmProjects/hse_proj/venv/lib/python3.7/site-packages/peewee.py", line 2512, in __exit__
    reraise(new_type, new_type(*exc_args), traceback)
  File "/Users/ivanshadrin/PycharmProjects/hse_proj/venv/lib/python3.7/site-packages/peewee.py", line 186, in reraise
    raise value.with_traceback(tb)
  File "/Users/ivanshadrin/PycharmProjects/hse_proj/venv/lib/python3.7/site-packages/peewee.py", line 2661, in connect
    self._state.set_connection(self._connect())
  File "/Users/ivanshadrin/PycharmProjects/hse_proj/venv/lib/python3.7/site-packages/peewee.py", line 2942, in _connect
    **self.connect_params)
peewee.OperationalError: unable to open database file
2019-03-16 19:29:24,434 [MainThread  ] [ERROR]  unable to open database file
Traceback (most recent call last):
  File "/Users/ivanshadrin/PycharmProjects/hse_proj/venv/lib/python3.7/site-packages/peewee.py", line 2661, in connect
    self._state.set_connection(self._connect())
  File "/Users/ivanshadrin/PycharmProjects/hse_proj/venv/lib/python3.7/site-packages/peewee.py", line 2942, in _connect
    **self.connect_params)
sqlite3.OperationalError: unable to open database file

During handling of the above exception, another exception occurred:

Traceback (most recent call last):
  File "/Users/ivanshadrin/PycharmProjects/hse_proj/venv/lib/python3.7/site-packages/peewee.py", line 2712, in execute_sql
    cursor = self.cursor(commit)
  File "/Users/ivanshadrin/PycharmProjects/hse_proj/venv/lib/python3.7/site-packages/peewee.py", line 2698, in cursor
    self.connect()
  File "/Users/ivanshadrin/PycharmProjects/hse_proj/venv/lib/python3.7/site-packages/peewee.py", line 2662, in connect
    self._initialize_connection(self._state.conn)
  File "/Users/ivanshadrin/PycharmProjects/hse_proj/venv/lib/python3.7/site-packages/peewee.py", line 2512, in __exit__
    reraise(new_type, new_type(*exc_args), traceback)
  File "/Users/ivanshadrin/PycharmProjects/hse_proj/venv/lib/python3.7/site-packages/peewee.py", line 186, in reraise
    raise value.with_traceback(tb)
  File "/Users/ivanshadrin/PycharmProjects/hse_proj/venv/lib/python3.7/site-packages/peewee.py", line 2661, in connect
    self._state.set_connection(self._connect())
  File "/Users/ivanshadrin/PycharmProjects/hse_proj/venv/lib/python3.7/site-packages/peewee.py", line 2942, in _connect
    **self.connect_params)
peewee.OperationalError: unable to open database file

During handling of the above exception, another exception occurred:

Traceback (most recent call last):
  File "/Users/ivanshadrin/PycharmProjects/hse_proj3/ls_source/run.py", line 40, in <module>
    from application import APP
  File "/Users/ivanshadrin/PycharmProjects/hse_proj3/ls_source/application.py", line 23, in <module>
    init_models(DB)
  File "/Users/ivanshadrin/PycharmProjects/hse_proj3/ls_source/models/__init__.py", line 14, in init_models
    db.database.create_tables(ms)
  File "/Users/ivanshadrin/PycharmProjects/hse_proj/venv/lib/python3.7/site-packages/peewee.py", line 2871, in create_tables
    model.create_table(**options)
  File "/Users/ivanshadrin/PycharmProjects/hse_proj/venv/lib/python3.7/site-packages/peewee.py", line 5846, in create_table
    cls._schema.create_all(safe, **options)
  File "/Users/ivanshadrin/PycharmProjects/hse_proj/venv/lib/python3.7/site-packages/peewee.py", line 5071, in create_all
    self.create_table(safe, **table_options)
  File "/Users/ivanshadrin/PycharmProjects/hse_proj/venv/lib/python3.7/site-packages/peewee.py", line 4957, in create_table
    self.database.execute(self._create_table(safe=safe, **options))
  File "/Users/ivanshadrin/PycharmProjects/hse_proj/venv/lib/python3.7/site-packages/peewee.py", line 2727, in execute
    return self.execute_sql(sql, params, commit=commit)
  File "/Users/ivanshadrin/PycharmProjects/hse_proj/venv/lib/python3.7/site-packages/peewee.py", line 2721, in execute_sql
    self.commit()
  File "/Users/ivanshadrin/PycharmProjects/hse_proj/venv/lib/python3.7/site-packages/peewee.py", line 2512, in __exit__
    reraise(new_type, new_type(*exc_args), traceback)
  File "/Users/ivanshadrin/PycharmProjects/hse_proj/venv/lib/python3.7/site-packages/peewee.py", line 186, in reraise
    raise value.with_traceback(tb)
  File "/Users/ivanshadrin/PycharmProjects/hse_proj/venv/lib/python3.7/site-packages/peewee.py", line 2712, in execute_sql
    cursor = self.cursor(commit)
  File "/Users/ivanshadrin/PycharmProjects/hse_proj/venv/lib/python3.7/site-packages/peewee.py", line 2698, in cursor
    self.connect()
  File "/Users/ivanshadrin/PycharmProjects/hse_proj/venv/lib/python3.7/site-packages/peewee.py", line 2662, in connect
    self._initialize_connection(self._state.conn)
  File "/Users/ivanshadrin/PycharmProjects/hse_proj/venv/lib/python3.7/site-packages/peewee.py", line 2512, in __exit__
    reraise(new_type, new_type(*exc_args), traceback)
  File "/Users/ivanshadrin/PycharmProjects/hse_proj/venv/lib/python3.7/site-packages/peewee.py", line 186, in reraise
    raise value.with_traceback(tb)
  File "/Users/ivanshadrin/PycharmProjects/hse_proj/venv/lib/python3.7/site-packages/peewee.py", line 2661, in connect
    self._state.set_connection(self._connect())
  File "/Users/ivanshadrin/PycharmProjects/hse_proj/venv/lib/python3.7/site-packages/peewee.py", line 2942, in _connect
    **self.connect_params)
peewee.OperationalError: unable to open database file
2019-03-16 19:29:30,500 [MainThread  ] [ERROR]  unable to open database file
Traceback (most recent call last):
  File "/Users/ivanshadrin/PycharmProjects/hse_proj/venv/lib/python3.7/site-packages/peewee.py", line 2661, in connect
    self._state.set_connection(self._connect())
  File "/Users/ivanshadrin/PycharmProjects/hse_proj/venv/lib/python3.7/site-packages/peewee.py", line 2942, in _connect
    **self.connect_params)
sqlite3.OperationalError: unable to open database file

During handling of the above exception, another exception occurred:

Traceback (most recent call last):
  File "/Users/ivanshadrin/PycharmProjects/hse_proj/venv/lib/python3.7/site-packages/peewee.py", line 2712, in execute_sql
    cursor = self.cursor(commit)
  File "/Users/ivanshadrin/PycharmProjects/hse_proj/venv/lib/python3.7/site-packages/peewee.py", line 2698, in cursor
    self.connect()
  File "/Users/ivanshadrin/PycharmProjects/hse_proj/venv/lib/python3.7/site-packages/peewee.py", line 2662, in connect
    self._initialize_connection(self._state.conn)
  File "/Users/ivanshadrin/PycharmProjects/hse_proj/venv/lib/python3.7/site-packages/peewee.py", line 2512, in __exit__
    reraise(new_type, new_type(*exc_args), traceback)
  File "/Users/ivanshadrin/PycharmProjects/hse_proj/venv/lib/python3.7/site-packages/peewee.py", line 186, in reraise
    raise value.with_traceback(tb)
  File "/Users/ivanshadrin/PycharmProjects/hse_proj/venv/lib/python3.7/site-packages/peewee.py", line 2661, in connect
    self._state.set_connection(self._connect())
  File "/Users/ivanshadrin/PycharmProjects/hse_proj/venv/lib/python3.7/site-packages/peewee.py", line 2942, in _connect
    **self.connect_params)
peewee.OperationalError: unable to open database file

During handling of the above exception, another exception occurred:

Traceback (most recent call last):
  File "/Users/ivanshadrin/PycharmProjects/hse_proj3/ls_source/run.py", line 40, in <module>
    from application import APP
  File "/Users/ivanshadrin/PycharmProjects/hse_proj3/ls_source/application.py", line 23, in <module>
    init_models(DB)
  File "/Users/ivanshadrin/PycharmProjects/hse_proj3/ls_source/models/__init__.py", line 14, in init_models
    db.database.create_tables(ms)
  File "/Users/ivanshadrin/PycharmProjects/hse_proj/venv/lib/python3.7/site-packages/peewee.py", line 2871, in create_tables
    model.create_table(**options)
  File "/Users/ivanshadrin/PycharmProjects/hse_proj/venv/lib/python3.7/site-packages/peewee.py", line 5846, in create_table
    cls._schema.create_all(safe, **options)
  File "/Users/ivanshadrin/PycharmProjects/hse_proj/venv/lib/python3.7/site-packages/peewee.py", line 5071, in create_all
    self.create_table(safe, **table_options)
  File "/Users/ivanshadrin/PycharmProjects/hse_proj/venv/lib/python3.7/site-packages/peewee.py", line 4957, in create_table
    self.database.execute(self._create_table(safe=safe, **options))
  File "/Users/ivanshadrin/PycharmProjects/hse_proj/venv/lib/python3.7/site-packages/peewee.py", line 2727, in execute
    return self.execute_sql(sql, params, commit=commit)
  File "/Users/ivanshadrin/PycharmProjects/hse_proj/venv/lib/python3.7/site-packages/peewee.py", line 2721, in execute_sql
    self.commit()
  File "/Users/ivanshadrin/PycharmProjects/hse_proj/venv/lib/python3.7/site-packages/peewee.py", line 2512, in __exit__
    reraise(new_type, new_type(*exc_args), traceback)
  File "/Users/ivanshadrin/PycharmProjects/hse_proj/venv/lib/python3.7/site-packages/peewee.py", line 186, in reraise
    raise value.with_traceback(tb)
  File "/Users/ivanshadrin/PycharmProjects/hse_proj/venv/lib/python3.7/site-packages/peewee.py", line 2712, in execute_sql
    cursor = self.cursor(commit)
  File "/Users/ivanshadrin/PycharmProjects/hse_proj/venv/lib/python3.7/site-packages/peewee.py", line 2698, in cursor
    self.connect()
  File "/Users/ivanshadrin/PycharmProjects/hse_proj/venv/lib/python3.7/site-packages/peewee.py", line 2662, in connect
    self._initialize_connection(self._state.conn)
  File "/Users/ivanshadrin/PycharmProjects/hse_proj/venv/lib/python3.7/site-packages/peewee.py", line 2512, in __exit__
    reraise(new_type, new_type(*exc_args), traceback)
  File "/Users/ivanshadrin/PycharmProjects/hse_proj/venv/lib/python3.7/site-packages/peewee.py", line 186, in reraise
    raise value.with_traceback(tb)
  File "/Users/ivanshadrin/PycharmProjects/hse_proj/venv/lib/python3.7/site-packages/peewee.py", line 2661, in connect
    self._state.set_connection(self._connect())
  File "/Users/ivanshadrin/PycharmProjects/hse_proj/venv/lib/python3.7/site-packages/peewee.py", line 2942, in _connect
    **self.connect_params)
peewee.OperationalError: unable to open database file
2019-03-16 19:34:03,328 [MainThread  ] [WARNI]   * Debugger is active!
2019-03-16 20:23:08,459 [MainThread  ] [WARNI]   * Debugger is active!
2019-03-16 22:42:55,120 [MainThread  ] [WARNI]   * Debugger is active!
2019-03-19 16:10:48,401 [MainThread  ] [WARNI]   * Debugger is active!
2019-03-19 17:01:05,966 [MainThread  ] [WARNI]   * Debugger is active!
2019-03-19 17:02:56,724 [MainThread  ] [WARNI]   * Debugger is active!
2019-03-19 17:04:08,835 [MainThread  ] [WARNI]   * Debugger is active!
2019-03-19 17:04:22,083 [MainThread  ] [WARNI]   * Debugger is active!
2019-03-19 17:09:38,737 [MainThread  ] [WARNI]   * Debugger is active!
2019-03-19 17:10:52,846 [MainThread  ] [WARNI]   * Debugger is active!
2019-03-19 17:12:42,769 [MainThread  ] [WARNI]   * Debugger is active!
2019-03-19 17:14:10,243 [MainThread  ] [WARNI]   * Debugger is active!
2019-03-19 17:15:45,754 [MainThread  ] [WARNI]   * Debugger is active!
2019-03-19 17:19:10,530 [MainThread  ] [WARNI]   * Debugger is active!
2019-03-19 17:21:20,673 [MainThread  ] [WARNI]   * Debugger is active!
2019-03-19 17:25:33,030 [MainThread  ] [WARNI]   * Debugger is active!
2019-03-19 17:30:36,357 [MainThread  ] [WARNI]   * Debugger is active!
2019-03-19 17:31:10,722 [MainThread  ] [WARNI]   * Debugger is active!
2019-03-19 17:31:43,835 [MainThread  ] [WARNI]   * Debugger is active!
2019-03-19 17:38:50,457 [MainThread  ] [WARNI]   * Debugger is active!
2019-03-19 17:52:50,670 [MainThread  ] [WARNI]   * Debugger is active!
2019-03-19 17:54:01,787 [MainThread  ] [WARNI]   * Debugger is active!
2019-03-19 17:57:00,238 [MainThread  ] [WARNI]   * Debugger is active!
2019-03-19 18:16:28,115 [MainThread  ] [WARNI]   * Debugger is active!
2019-03-19 18:17:11,723 [MainThread  ] [WARNI]   * Debugger is active!
2019-03-19 18:18:25,856 [MainThread  ] [WARNI]   * Debugger is active!
2019-03-19 18:24:52,141 [MainThread  ] [WARNI]   * Debugger is active!
2019-03-19 18:25:50,917 [MainThread  ] [WARNI]   * Debugger is active!
2019-03-19 18:29:02,408 [MainThread  ] [WARNI]   * Debugger is active!
2019-03-19 18:29:42,928 [MainThread  ] [WARNI]   * Debugger is active!
2019-03-19 18:30:14,242 [MainThread  ] [WARNI]   * Debugger is active!
2019-03-19 18:34:49,692 [MainThread  ] [WARNI]   * Debugger is active!
2019-03-19 18:36:07,948 [MainThread  ] [WARNI]   * Debugger is active!
2019-03-19 18:38:05,824 [MainThread  ] [ERROR]  invalid syntax (customer.py, line 122)
Traceback (most recent call last):
  File "/Users/ivanshadrin/PycharmProjects/hse_proj3/ls_source/run.py", line 40, in <module>
    from application import APP
  File "/Users/ivanshadrin/PycharmProjects/hse_proj3/ls_source/application.py", line 50, in <module>
    from services.customer import GetCustomer, GetCustomers, AddCustomer, DeleteCustomer, UpdateCustomer
  File "/Users/ivanshadrin/PycharmProjects/hse_proj3/ls_source/services/customer.py", line 122
    """
            email=args["email"],
            phone=args["phone"],
            birth_day=args["birth_day"],
            district=args["district"],
            address=args["address"],
            linked_card=args["linked_card"])""".where(Customer.customer_id == customer_id)
       
                                
                                
                                        
                                      
                                    
                                              ^
SyntaxError: invalid syntax
2019-03-19 18:38:15,866 [MainThread  ] [ERROR]  invalid syntax (customer.py, line 122)
Traceback (most recent call last):
  File "/Users/ivanshadrin/PycharmProjects/hse_proj3/ls_source/run.py", line 40, in <module>
    from application import APP
  File "/Users/ivanshadrin/PycharmProjects/hse_proj3/ls_source/application.py", line 50, in <module>
    from services.customer import GetCustomer, GetCustomers, AddCustomer, DeleteCustomer, UpdateCustomer
  File "/Users/ivanshadrin/PycharmProjects/hse_proj3/ls_source/services/customer.py", line 122
    """
            email=args["email"],
            phone=args["phone"],
            birth_day=args["birth_day"],
            district=args["district"],
            address=args["address"],
            linked_card=args["linked_card"])""".where(Customer.customer_id == customer_id)
       
                                
                                
                                        
                                      
                                    
                                              ^
SyntaxError: invalid syntax
2019-03-19 18:38:27,084 [MainThread  ] [ERROR]  unexpected indent (customer.py, line 116)
Traceback (most recent call last):
  File "/Users/ivanshadrin/PycharmProjects/hse_proj3/ls_source/run.py", line 40, in <module>
    from application import APP
  File "/Users/ivanshadrin/PycharmProjects/hse_proj3/ls_source/application.py", line 50, in <module>
    from services.customer import GetCustomer, GetCustomers, AddCustomer, DeleteCustomer, UpdateCustomer
  File "/Users/ivanshadrin/PycharmProjects/hse_proj3/ls_source/services/customer.py", line 116
    """
    ^
IndentationError: unexpected indent
2019-03-19 18:39:02,438 [MainThread  ] [ERROR]  unexpected indent (customer.py, line 116)
Traceback (most recent call last):
  File "/Users/ivanshadrin/PycharmProjects/hse_proj3/ls_source/run.py", line 40, in <module>
    from application import APP
  File "/Users/ivanshadrin/PycharmProjects/hse_proj3/ls_source/application.py", line 50, in <module>
    from services.customer import GetCustomer, GetCustomers, AddCustomer, DeleteCustomer, UpdateCustomer
  File "/Users/ivanshadrin/PycharmProjects/hse_proj3/ls_source/services/customer.py", line 116
    """
    ^
IndentationError: unexpected indent
2019-03-19 18:39:10,369 [MainThread  ] [WARNI]   * Debugger is active!
2019-03-19 18:40:22,217 [MainThread  ] [ERROR]  unexpected indent (customer.py, line 116)
Traceback (most recent call last):
  File "/Users/ivanshadrin/PycharmProjects/hse_proj3/ls_source/run.py", line 40, in <module>
    from application import APP
  File "/Users/ivanshadrin/PycharmProjects/hse_proj3/ls_source/application.py", line 50, in <module>
    from services.customer import GetCustomer, GetCustomers, AddCustomer, DeleteCustomer, UpdateCustomer
  File "/Users/ivanshadrin/PycharmProjects/hse_proj3/ls_source/services/customer.py", line 116
    email=args["email"],
    ^
IndentationError: unexpected indent
2019-03-19 18:40:26,731 [MainThread  ] [ERROR]  unexpected indent (customer.py, line 116)
Traceback (most recent call last):
  File "/Users/ivanshadrin/PycharmProjects/hse_proj3/ls_source/run.py", line 40, in <module>
    from application import APP
  File "/Users/ivanshadrin/PycharmProjects/hse_proj3/ls_source/application.py", line 50, in <module>
    from services.customer import GetCustomer, GetCustomers, AddCustomer, DeleteCustomer, UpdateCustomer
  File "/Users/ivanshadrin/PycharmProjects/hse_proj3/ls_source/services/customer.py", line 116
    email=args["email"],
    ^
IndentationError: unexpected indent
2019-03-19 18:42:15,461 [MainThread  ] [WARNI]   * Debugger is active!
2019-03-20 00:49:54,424 [MainThread  ] [ERROR]  unexpected indent (customer.py, line 63)
Traceback (most recent call last):
  File "/Users/ivanshadrin/PycharmProjects/hse_proj3/ls_source/run.py", line 40, in <module>
    from application import APP
  File "/Users/ivanshadrin/PycharmProjects/hse_proj3/ls_source/application.py", line 50, in <module>
    from services.customer import GetCustomer, GetCustomers, AddCustomer, DeleteCustomer, UpdateCustomer
  File "/Users/ivanshadrin/PycharmProjects/hse_proj3/ls_source/services/customer.py", line 63
    """   first_name=args["first_name"],
    ^
IndentationError: unexpected indent
2019-03-20 00:50:10,377 [MainThread  ] [ERROR]  unexpected indent (customer.py, line 63)
Traceback (most recent call last):
  File "/Users/ivanshadrin/PycharmProjects/hse_proj3/ls_source/run.py", line 40, in <module>
    from application import APP
  File "/Users/ivanshadrin/PycharmProjects/hse_proj3/ls_source/application.py", line 50, in <module>
    from services.customer import GetCustomer, GetCustomers, AddCustomer, DeleteCustomer, UpdateCustomer
  File "/Users/ivanshadrin/PycharmProjects/hse_proj3/ls_source/services/customer.py", line 63
    """   first_name=args["first_name"],
    ^
IndentationError: unexpected indent
2019-03-20 00:50:32,861 [MainThread  ] [WARNI]   * Debugger is active!
2019-03-20 01:20:36,194 [MainThread  ] [WARNI]   * Debugger is active!
2019-03-20 01:22:25,679 [MainThread  ] [WARNI]   * Debugger is active!
2019-03-20 01:22:55,740 [MainThread  ] [WARNI]   * Debugger is active!
2019-03-20 01:33:56,282 [MainThread  ] [WARNI]   * Debugger is active!
2019-03-20 01:37:10,325 [MainThread  ] [WARNI]   * Debugger is active!
2019-03-20 01:42:25,148 [MainThread  ] [WARNI]   * Debugger is active!
2019-03-20 01:48:32,486 [MainThread  ] [WARNI]   * Debugger is active!
2019-03-20 01:48:49,237 [MainThread  ] [WARNI]   * Debugger is active!
2019-03-20 01:50:25,599 [MainThread  ] [WARNI]   * Debugger is active!
2019-03-20 01:51:24,036 [MainThread  ] [WARNI]   * Debugger is active!
2019-03-20 01:52:08,210 [MainThread  ] [WARNI]   * Debugger is active!
2019-03-20 01:52:32,038 [MainThread  ] [WARNI]   * Debugger is active!
2019-03-20 01:53:38,640 [MainThread  ] [WARNI]   * Debugger is active!
2019-03-20 01:53:47,812 [MainThread  ] [WARNI]   * Debugger is active!
2019-03-20 11:26:07,608 [MainThread  ] [WARNI]   * Debugger is active!
2019-03-20 11:33:37,107 [MainThread  ] [WARNI]   * Debugger is active!
2019-03-20 11:34:20,429 [MainThread  ] [WARNI]   * Debugger is active!
2019-03-20 11:44:54,494 [MainThread  ] [WARNI]   * Debugger is active!
2019-03-20 11:46:26,884 [MainThread  ] [WARNI]   * Debugger is active!
2019-03-20 11:46:45,611 [MainThread  ] [WARNI]   * Debugger is active!
2019-03-20 11:57:26,325 [MainThread  ] [WARNI]   * Debugger is active!
2019-03-20 11:58:22,783 [MainThread  ] [WARNI]   * Debugger is active!
2019-03-20 12:04:56,855 [MainThread  ] [ERROR]  invalid syntax (product.py, line 35)
Traceback (most recent call last):
  File "/Users/ivanshadrin/PycharmProjects/hse_proj3/ls_source/run.py", line 40, in <module>
    from application import APP
  File "/Users/ivanshadrin/PycharmProjects/hse_proj3/ls_source/application.py", line 40, in <module>
    from services.product import GetProducts, AddProduct, DeleteProduct, UpdateProduct
  File "/Users/ivanshadrin/PycharmProjects/hse_proj3/ls_source/services/product.py", line 35
    def post(self, category_id):
      ^
SyntaxError: invalid syntax
2019-03-20 12:06:49,103 [MainThread  ] [WARNI]   * Debugger is active!
2019-03-20 12:07:23,122 [MainThread  ] [WARNI]   * Debugger is active!
2019-03-20 12:11:34,078 [MainThread  ] [WARNI]   * Debugger is active!
2019-03-20 12:11:50,831 [MainThread  ] [WARNI]   * Debugger is active!
2019-03-20 12:15:45,636 [MainThread  ] [ERROR]  keyword can't be an expression (product.py, line 58)
Traceback (most recent call last):
  File "/Users/ivanshadrin/PycharmProjects/hse_proj3/ls_source/run.py", line 40, in <module>
    from application import APP
  File "/Users/ivanshadrin/PycharmProjects/hse_proj3/ls_source/application.py", line 40, in <module>
    from services.product import GetProducts, AddProduct, DeleteProduct, UpdateProduct
  File "/Users/ivanshadrin/PycharmProjects/hse_proj3/ls_source/services/product.py", line 58
    query = Product.update(**args).where(Product.product_id = product_id)
                                        ^
SyntaxError: keyword can't be an expression
2019-03-20 12:16:57,890 [MainThread  ] [WARNI]   * Debugger is active!
2019-03-20 12:20:14,400 [MainThread  ] [WARNI]   * Debugger is active!
2019-03-20 12:21:44,895 [MainThread  ] [WARNI]   * Debugger is active!
2019-03-20 12:21:51,503 [Thread-2    ] [CRITI]  1
2019-03-20 12:21:51,506 [Thread-2    ] [CRITI]  <peewee.ModelUpdate object at 0x106483320>
2019-03-20 12:26:59,350 [MainThread  ] [WARNI]   * Debugger is active!
2019-03-20 12:27:05,277 [Thread-2    ] [CRITI]  1
2019-03-20 12:27:05,280 [Thread-2    ] [CRITI]  None
2019-03-20 12:27:22,175 [MainThread  ] [WARNI]   * Debugger is active!
2019-03-20 12:32:55,793 [MainThread  ] [WARNI]   * Debugger is active!
2019-03-20 12:32:58,054 [Thread-2    ] [CRITI]  1
2019-03-20 12:34:05,629 [MainThread  ] [WARNI]   * Debugger is active!
2019-03-20 12:34:06,825 [Thread-2    ] [CRITI]  1
2019-03-20 12:34:06,826 [Thread-2    ] [CRITI]  {}
2019-03-20 12:35:02,144 [MainThread  ] [WARNI]   * Debugger is active!
2019-03-20 12:35:04,526 [Thread-2    ] [CRITI]  1
2019-03-20 12:35:04,527 [Thread-2    ] [CRITI]  {'price': 199.0}
2019-03-20 12:35:04,527 [Thread-2    ] [CRITI]  <peewee.ModelUpdate object at 0x10c8bb470>
2019-03-20 12:36:00,283 [Thread-7    ] [CRITI]  1
2019-03-20 12:36:00,284 [Thread-7    ] [CRITI]  {'price': 199.0}
2019-03-20 12:36:00,284 [Thread-7    ] [CRITI]  <peewee.ModelUpdate object at 0x10c8bb7b8>
2019-03-20 12:36:23,987 [MainThread  ] [WARNI]   * Debugger is active!
2019-03-20 12:36:53,931 [MainThread  ] [WARNI]   * Debugger is active!
2019-03-20 12:37:13,399 [Thread-2    ] [CRITI]  1
2019-03-20 12:37:13,400 [Thread-2    ] [CRITI]  {'price': 200.0}
2019-03-20 12:37:13,400 [Thread-2    ] [CRITI]  <peewee.ModelUpdate object at 0x10b740438>
2019-03-20 12:38:30,036 [MainThread  ] [WARNI]   * Debugger is active!
2019-03-20 12:40:30,170 [Thread-4    ] [CRITI]  {'first_name': 'Новый-Старый', 'last_name': 'Клиент', 'email': None, 'phone': None, 'birth_day': None, 'district': None, 'address': None, 'linked_card': None}
2019-03-20 12:43:13,929 [MainThread  ] [WARNI]   * Debugger is active!
2019-03-20 12:43:17,320 [Thread-2    ] [CRITI]  {'first_name': 'Новый-Старый', 'last_name': 'Клиент', 'email': None, 'phone': None, 'birth_day': None, 'district': None, 'address': None, 'linked_card': None}
2019-03-20 12:43:40,217 [MainThread  ] [WARNI]   * Debugger is active!
2019-03-20 12:43:40,692 [Thread-2    ] [CRITI]  {'first_name': 'Новый-Старый', 'last_name': 'Клиент', 'email': None, 'phone': None, 'birth_day': None, 'district': None, 'address': None, 'linked_card': None}
2019-03-20 12:43:49,019 [MainThread  ] [WARNI]   * Debugger is active!
2019-03-20 12:46:38,788 [MainThread  ] [WARNI]   * Debugger is active!
2019-03-20 12:46:45,903 [Thread-2    ] [CRITI]  {}
2019-03-20 12:47:36,324 [MainThread  ] [WARNI]   * Debugger is active!
2019-03-20 12:47:39,050 [Thread-2    ] [CRITI]  {'first_name': 'Новый-Старый', 'last_name': 'Клиент', 'email': None, 'phone': None, 'birth_day': None, 'district': None, 'address': None, 'linked_card': None}
2019-03-20 12:49:28,165 [MainThread  ] [WARNI]   * Debugger is active!
2019-03-20 12:49:30,877 [Thread-2    ] [CRITI]  {'first_name': 'Новый-Старый', 'last_name': 'Клиент', 'email': None, 'phone': None, 'birth_day': None, 'district': None, 'address': None, 'linked_card': None}
2019-03-20 12:51:18,734 [MainThread  ] [WARNI]   * Debugger is active!
2019-03-20 12:52:37,979 [MainThread  ] [WARNI]   * Debugger is active!
2019-03-20 12:52:50,605 [MainThread  ] [WARNI]   * Debugger is active!
2019-03-20 12:53:02,471 [MainThread  ] [WARNI]   * Debugger is active!
2019-03-20 12:53:04,435 [Thread-2    ] [CRITI]  {'first_name': 'Новый-Старый', 'last_name': 'Клиент'}
2019-03-20 12:53:34,689 [MainThread  ] [WARNI]   * Debugger is active!
2019-03-20 12:53:58,791 [MainThread  ] [WARNI]   * Debugger is active!
2019-03-20 12:54:05,513 [MainThread  ] [WARNI]   * Debugger is active!
2019-03-20 12:54:50,722 [MainThread  ] [WARNI]   * Debugger is active!
2019-03-20 13:03:39,603 [MainThread  ] [WARNI]   * Debugger is active!
2019-03-20 13:06:51,944 [MainThread  ] [WARNI]   * Debugger is active!
2019-03-20 13:06:59,556 [MainThread  ] [ERROR]  invalid syntax (categories.py, line 35)
Traceback (most recent call last):
  File "/Users/ivanshadrin/PycharmProjects/hse_proj3/ls_source/run.py", line 40, in <module>
    from application import APP
  File "/Users/ivanshadrin/PycharmProjects/hse_proj3/ls_source/application.py", line 46, in <module>
    from services.categories import AddCategory, GetCategories
  File "/Users/ivanshadrin/PycharmProjects/hse_proj3/ls_source/services/categories.py", line 35
    def del(self, category_id):
          ^
SyntaxError: invalid syntax
2019-03-20 13:07:29,065 [MainThread  ] [WARNI]   * Debugger is active!
2019-03-20 13:08:31,602 [MainThread  ] [WARNI]   * Debugger is active!
2019-03-20 13:09:41,218 [MainThread  ] [WARNI]   * Debugger is active!
2019-03-20 13:10:53,572 [Thread-3    ] [ERROR]  127.0.0.1 - - [20/Mar/2019 13:10:53] code 400, message Bad request syntax ('POST /categories/add/\x1f8FF0 HTTP/1.1')
2019-03-20 13:11:12,803 [Thread-4    ] [ERROR]  127.0.0.1 - - [20/Mar/2019 13:11:12] code 400, message Bad request syntax ('POST /category/add/\x1f8FF0 HTTP/1.1')
2019-03-20 13:11:58,217 [MainThread  ] [WARNI]   * Debugger is active!
2019-03-20 13:13:02,889 [MainThread  ] [WARNI]   * Debugger is active!
2019-03-20 13:14:03,837 [MainThread  ] [WARNI]   * Debugger is active!
2019-03-20 13:14:17,504 [MainThread  ] [WARNI]   * Debugger is active!
2019-03-20 13:14:47,758 [MainThread  ] [WARNI]   * Debugger is active!
2019-03-20 13:18:43,850 [MainThread  ] [WARNI]   * Debugger is active!
2019-03-20 13:21:33,688 [MainThread  ] [ERROR]  invalid syntax (categories.py, line 48)
Traceback (most recent call last):
  File "/Users/ivanshadrin/PycharmProjects/hse_proj3/ls_source/run.py", line 40, in <module>
    from application import APP
  File "/Users/ivanshadrin/PycharmProjects/hse_proj3/ls_source/application.py", line 46, in <module>
    from services.categories import AddCategory, GetCategories, DeleteCategory
  File "/Users/ivanshadrin/PycharmProjects/hse_proj3/ls_source/services/categories.py", line 48
    TODO: добавить update
                        ^
SyntaxError: invalid syntax
2019-03-20 13:23:26,219 [MainThread  ] [WARNI]   * Debugger is active!
2019-03-20 13:36:33,801 [MainThread  ] [WARNI]   * Debugger is active!
2019-03-20 13:38:35,959 [MainThread  ] [WARNI]   * Debugger is active!
2019-03-20 13:42:01,669 [MainThread  ] [WARNI]   * Debugger is active!
2019-03-20 13:47:07,066 [MainThread  ] [WARNI]   * Debugger is active!
2019-03-20 13:47:59,458 [MainThread  ] [WARNI]   * Debugger is active!
2019-03-20 13:48:02,070 [Thread-2    ] [WARNI]  <peewee.ModelSelect object at 0x10ddb7e10>
2019-03-20 13:48:54,085 [Thread-3    ] [WARNI]  <peewee.ModelSelect object at 0x10e00dda0>
2019-03-20 13:57:12,499 [MainThread  ] [WARNI]   * Debugger is active!
2019-03-20 13:57:41,676 [MainThread  ] [WARNI]   * Debugger is active!
2019-03-20 13:57:47,771 [Thread-2    ] [WARNI]  1
2019-03-20 13:58:54,783 [MainThread  ] [ERROR]  invalid syntax (order.py, line 18)
Traceback (most recent call last):
  File "/Users/ivanshadrin/PycharmProjects/hse_proj3/ls_source/run.py", line 40, in <module>
    from application import APP
  File "/Users/ivanshadrin/PycharmProjects/hse_proj3/ls_source/application.py", line 58, in <module>
    from services.order import GetOrders, AddOrder, DeleteOrder, UpdateOrder
  File "/Users/ivanshadrin/PycharmProjects/hse_proj3/ls_source/services/order.py", line 18
    row = model_to_dict(order, exclude=[Order.create_time, Order.customer_id.])
                                                                             ^
SyntaxError: invalid syntax
2019-03-20 13:59:10,811 [MainThread  ] [WARNI]   * Debugger is active!
2019-03-20 13:59:45,956 [MainThread  ] [WARNI]   * Debugger is active!
2019-03-20 13:59:48,552 [Thread-2    ] [WARNI]  1
2019-03-20 14:01:00,026 [MainThread  ] [WARNI]   * Debugger is active!
2019-03-20 14:01:08,862 [MainThread  ] [WARNI]   * Debugger is active!
2019-03-20 14:03:59,815 [MainThread  ] [WARNI]   * Debugger is active!
2019-03-20 14:10:54,313 [MainThread  ] [WARNI]   * Debugger is active!
2019-03-20 14:54:31,099 [MainThread  ] [WARNI]   * Debugger is active!
2019-03-20 15:20:55,070 [MainThread  ] [WARNI]   * Debugger is active!
2019-03-20 16:02:34,733 [MainThread  ] [WARNI]   * Debugger is active!
2019-03-20 16:02:57,885 [MainThread  ] [WARNI]   * Debugger is active!
2019-03-20 16:03:07,402 [MainThread  ] [WARNI]   * Debugger is active!
2019-03-20 16:03:09,089 [MainThread  ] [WARNI]   * Debugger is active!
2019-03-20 16:04:49,857 [MainThread  ] [WARNI]   * Debugger is active!
2019-03-20 16:05:22,819 [MainThread  ] [WARNI]   * Debugger is active!
2019-03-20 16:07:12,296 [MainThread  ] [WARNI]   * Debugger is active!
2019-03-20 16:30:19,729 [MainThread  ] [WARNI]   * Debugger is active!
2019-03-20 16:31:32,431 [MainThread  ] [WARNI]   * Debugger is active!
2019-03-20 16:33:56,795 [MainThread  ] [WARNI]   * Debugger is active!
2019-03-20 16:34:21,642 [MainThread  ] [WARNI]   * Debugger is active!
2019-03-20 16:37:31,820 [MainThread  ] [WARNI]   * Debugger is active!
2019-03-20 16:40:32,042 [MainThread  ] [WARNI]   * Debugger is active!
2019-03-20 16:42:04,420 [MainThread  ] [WARNI]   * Debugger is active!
2019-03-20 16:42:10,212 [MainThread  ] [WARNI]   * Debugger is active!
2019-03-20 16:42:46,566 [MainThread  ] [WARNI]   * Debugger is active!
2019-03-20 16:43:36,560 [MainThread  ] [WARNI]   * Debugger is active!
2019-03-20 16:46:07,009 [MainThread  ] [WARNI]   * Debugger is active!
2019-03-20 16:46:27,810 [MainThread  ] [WARNI]   * Debugger is active!
2019-03-20 16:48:54,028 [MainThread  ] [WARNI]   * Debugger is active!
2019-03-20 16:52:31,428 [MainThread  ] [WARNI]   * Debugger is active!
2019-03-20 16:52:49,138 [MainThread  ] [WARNI]   * Debugger is active!
2019-03-20 16:55:18,326 [MainThread  ] [WARNI]   * Debugger is active!
2019-03-20 16:56:14,741 [Thread-2    ] [CRITI]  None
2019-03-20 16:56:14,741 [Thread-2    ] [CRITI]  None
2019-03-20 17:01:59,234 [MainThread  ] [WARNI]   * Debugger is active!
2019-03-20 17:04:52,254 [MainThread  ] [WARNI]   * Debugger is active!
2019-03-20 17:07:18,317 [MainThread  ] [WARNI]   * Debugger is active!
2019-03-20 17:08:36,415 [MainThread  ] [WARNI]   * Debugger is active!
2019-03-20 17:09:40,483 [Thread-8    ] [CRITI]  None
2019-03-20 17:09:40,484 [Thread-8    ] [CRITI]  None
2019-03-20 17:15:03,366 [MainThread  ] [WARNI]   * Debugger is active!
2019-03-20 17:28:27,542 [MainThread  ] [WARNI]   * Debugger is active!
2019-03-20 17:28:39,166 [MainThread  ] [WARNI]   * Debugger is active!
2019-03-20 17:28:44,492 [Thread-2    ] [CRITI]  None
2019-03-20 17:28:44,493 [Thread-2    ] [CRITI]  None
2019-03-20 17:34:59,836 [MainThread  ] [WARNI]   * Debugger is active!
2019-03-20 17:45:12,999 [Thread-2    ] [CRITI]  None
2019-03-20 17:45:13,000 [Thread-2    ] [CRITI]  None
2019-03-20 19:03:46,775 [MainThread  ] [WARNI]   * Debugger is active!
2019-03-20 19:03:53,000 [Thread-2    ] [CRITI]  1
2019-03-20 19:03:53,003 [Thread-2    ] [CRITI]  2
2019-03-20 19:04:36,252 [MainThread  ] [WARNI]   * Debugger is active!
2019-03-20 19:09:14,808 [MainThread  ] [WARNI]   * Debugger is active!
2019-03-20 19:12:57,731 [MainThread  ] [WARNI]   * Debugger is active!
2019-03-20 19:13:32,171 [MainThread  ] [WARNI]   * Debugger is active!
2019-03-20 19:15:03,323 [MainThread  ] [WARNI]   * Debugger is active!
2019-03-20 19:16:57,111 [MainThread  ] [WARNI]   * Debugger is active!
2019-03-20 19:18:10,904 [MainThread  ] [WARNI]   * Debugger is active!
2019-03-20 19:18:57,598 [MainThread  ] [WARNI]   * Debugger is active!
2019-03-20 19:38:32,480 [MainThread  ] [WARNI]   * Debugger is active!
2019-03-20 19:39:30,127 [MainThread  ] [WARNI]   * Debugger is active!
2019-03-20 19:40:35,751 [MainThread  ] [WARNI]   * Debugger is active!
2019-03-20 19:44:28,169 [MainThread  ] [WARNI]   * Debugger is active!
2019-03-20 19:44:45,941 [MainThread  ] [WARNI]   * Debugger is active!
2019-03-20 19:47:18,592 [MainThread  ] [WARNI]   * Debugger is active!
2019-03-20 22:46:35,297 [MainThread  ] [WARNI]   * Debugger is active!
2019-04-08 17:08:03,881 [MainThread  ] [WARNI]   * Debugger is active!
2019-04-08 17:10:15,019 [MainThread  ] [WARNI]   * Debugger is active!
2019-04-08 17:16:12,274 [MainThread  ] [WARNI]   * Debugger is active!
2019-04-08 17:16:37,409 [MainThread  ] [WARNI]   * Debugger is active!
2019-04-08 17:18:35,131 [MainThread  ] [WARNI]   * Debugger is active!
2019-04-08 17:35:24,326 [MainThread  ] [WARNI]   * Debugger is active!
2019-04-08 17:40:18,263 [MainThread  ] [WARNI]   * Debugger is active!
2019-04-08 17:52:13,635 [MainThread  ] [WARNI]   * Debugger is active!
2019-04-08 17:55:21,735 [MainThread  ] [WARNI]   * Debugger is active!
2019-04-08 17:55:43,920 [MainThread  ] [WARNI]   * Debugger is active!
2019-04-08 18:03:09,715 [MainThread  ] [WARNI]   * Debugger is active!
2019-04-08 18:05:11,740 [MainThread  ] [WARNI]   * Debugger is active!
2019-04-08 18:05:39,786 [MainThread  ] [WARNI]   * Debugger is active!
2019-04-08 18:08:21,922 [MainThread  ] [WARNI]   * Debugger is active!
2019-04-08 18:10:50,440 [MainThread  ] [WARNI]   * Debugger is active!
2019-04-08 18:16:09,632 [MainThread  ] [WARNI]   * Debugger is active!
2019-04-08 18:32:27,738 [MainThread  ] [WARNI]   * Debugger is active!
2019-04-08 18:40:37,085 [MainThread  ] [WARNI]   * Debugger is active!
2019-04-08 18:40:41,706 [MainThread  ] [WARNI]   * Debugger is active!
2019-04-08 18:41:34,467 [MainThread  ] [WARNI]   * Debugger is active!
2019-04-08 21:56:54,861 [MainThread  ] [WARNI]   * Debugger is active!
2019-04-08 21:59:29,059 [MainThread  ] [WARNI]   * Debugger is active!
2019-04-08 22:01:18,791 [MainThread  ] [WARNI]   * Debugger is active!
2019-04-08 22:02:40,118 [MainThread  ] [WARNI]   * Debugger is active!
2019-04-08 22:03:15,607 [MainThread  ] [WARNI]   * Debugger is active!
2019-04-08 22:05:50,083 [MainThread  ] [WARNI]   * Debugger is active!
2019-04-08 22:06:11,935 [MainThread  ] [ERROR]  invalid syntax (order.py, line 38)
Traceback (most recent call last):
  File "/Users/ivanshadrin/PycharmProjects/hse_proj3/ls_source/run.py", line 40, in <module>
    from application import APP
  File "/Users/ivanshadrin/PycharmProjects/hse_proj3/ls_source/application.py", line 23, in <module>
    init_models(DB)
  File "/Users/ivanshadrin/PycharmProjects/hse_proj3/ls_source/models/__init__.py", line 8, in init_models
    from models.order import Order, OrderItem
  File "/Users/ivanshadrin/PycharmProjects/hse_proj3/ls_source/models/order.py", line 38
    query = Producer.select().where(Producer.district == cls..district)  # Вручную тут вылезает ошибка
                                                             ^
SyntaxError: invalid syntax
2019-04-08 22:06:18,298 [MainThread  ] [WARNI]   * Debugger is active!
2019-04-08 22:10:51,041 [MainThread  ] [WARNI]   * Debugger is active!
2019-04-08 22:11:45,512 [MainThread  ] [WARNI]   * Debugger is active!
2019-04-08 22:12:15,817 [MainThread  ] [WARNI]   * Debugger is active!
2019-04-08 22:19:39,752 [MainThread  ] [WARNI]   * Debugger is active!
2019-04-08 22:21:22,405 [MainThread  ] [WARNI]   * Debugger is active!
2019-04-08 22:21:42,486 [MainThread  ] [WARNI]   * Debugger is active!
2019-04-08 22:24:48,521 [MainThread  ] [WARNI]   * Debugger is active!
2019-04-08 22:59:26,990 [MainThread  ] [WARNI]   * Debugger is active!
2019-04-08 22:59:47,142 [MainThread  ] [WARNI]   * Debugger is active!
2019-04-08 23:06:11,491 [MainThread  ] [WARNI]   * Debugger is active!
2019-04-08 23:09:30,293 [MainThread  ] [WARNI]   * Debugger is active!
2019-04-08 23:11:40,036 [MainThread  ] [WARNI]   * Debugger is active!
2019-04-08 23:16:17,750 [MainThread  ] [WARNI]   * Debugger is active!
2019-04-08 23:18:41,129 [MainThread  ] [WARNI]   * Debugger is active!
2019-04-08 23:21:49,070 [MainThread  ] [WARNI]   * Debugger is active!
2019-04-08 23:21:54,569 [MainThread  ] [WARNI]   * Debugger is active!
2019-04-08 23:23:12,204 [MainThread  ] [WARNI]   * Debugger is active!
2019-04-08 23:25:23,284 [MainThread  ] [WARNI]   * Debugger is active!
2019-04-08 23:28:30,611 [MainThread  ] [WARNI]   * Debugger is active!
2019-04-10 20:17:41,492 [MainThread  ] [WARNI]   * Debugger is active!
2019-04-10 20:42:42,842 [MainThread  ] [WARNI]   * Debugger is active!
2019-04-10 21:39:53,964 [MainThread  ] [WARNI]   * Debugger is active!
2019-04-10 21:46:15,978 [MainThread  ] [WARNI]   * Debugger is active!
2019-04-10 21:48:59,728 [MainThread  ] [WARNI]   * Debugger is active!
2019-04-10 21:49:35,967 [MainThread  ] [WARNI]   * Debugger is active!
2019-04-10 21:51:59,306 [MainThread  ] [WARNI]   * Debugger is active!
